Processing model 1...
Loaded embeddings with shape: (323432, 100)
Traceback (most recent call last):
  File "/home/gpuuser1/gpuuser1_a/sandeep/sandeep/ndd/Neighbourhood quality/KNN_learning-opt3.py", line 124, in <module>
    main()
  File "/home/gpuuser1/gpuuser1_a/sandeep/sandeep/ndd/Neighbourhood quality/KNN_learning-opt3.py", line 101, in main
    subsample_labels = train_labels[subsample_indices]
IndexError: index 209095 is out of bounds for axis 0 with size 40429
Completed processing for model 1
------------------------------
Processing model 2...
Loaded embeddings with shape: (323432, 100)
Traceback (most recent call last):
  File "/home/gpuuser1/gpuuser1_a/sandeep/sandeep/ndd/Neighbourhood quality/KNN_learning-opt3.py", line 124, in <module>
    main()
  File "/home/gpuuser1/gpuuser1_a/sandeep/sandeep/ndd/Neighbourhood quality/KNN_learning-opt3.py", line 101, in main
    subsample_labels = train_labels[subsample_indices]
IndexError: index 162371 is out of bounds for axis 0 with size 40429
Completed processing for model 2
------------------------------
Processing model 3...
Loaded embeddings with shape: (323432, 100)
Traceback (most recent call last):
  File "/home/gpuuser1/gpuuser1_a/sandeep/sandeep/ndd/Neighbourhood quality/KNN_learning-opt3.py", line 124, in <module>
    main()
  File "/home/gpuuser1/gpuuser1_a/sandeep/sandeep/ndd/Neighbourhood quality/KNN_learning-opt3.py", line 101, in main
    subsample_labels = train_labels[subsample_indices]
IndexError: index 94342 is out of bounds for axis 0 with size 40429
Completed processing for model 3
------------------------------
Processing model 4...
Loaded embeddings with shape: (323432, 100)
Traceback (most recent call last):
  File "/home/gpuuser1/gpuuser1_a/sandeep/sandeep/ndd/Neighbourhood quality/KNN_learning-opt3.py", line 124, in <module>
    main()
  File "/home/gpuuser1/gpuuser1_a/sandeep/sandeep/ndd/Neighbourhood quality/KNN_learning-opt3.py", line 101, in main
    subsample_labels = train_labels[subsample_indices]
IndexError: index 208290 is out of bounds for axis 0 with size 40429
Completed processing for model 4
------------------------------
Processing model 5...
Loaded embeddings with shape: (323432, 100)
Traceback (most recent call last):
  File "/home/gpuuser1/gpuuser1_a/sandeep/sandeep/ndd/Neighbourhood quality/KNN_learning-opt3.py", line 124, in <module>
    main()
  File "/home/gpuuser1/gpuuser1_a/sandeep/sandeep/ndd/Neighbourhood quality/KNN_learning-opt3.py", line 101, in main
    subsample_labels = train_labels[subsample_indices]
IndexError: index 159758 is out of bounds for axis 0 with size 40429
Completed processing for model 5
------------------------------
Processing model 6...
Loaded embeddings with shape: (323432, 100)
Traceback (most recent call last):
  File "/home/gpuuser1/gpuuser1_a/sandeep/sandeep/ndd/Neighbourhood quality/KNN_learning-opt3.py", line 124, in <module>
    main()
  File "/home/gpuuser1/gpuuser1_a/sandeep/sandeep/ndd/Neighbourhood quality/KNN_learning-opt3.py", line 101, in main
    subsample_labels = train_labels[subsample_indices]
IndexError: index 277142 is out of bounds for axis 0 with size 40429
Completed processing for model 6
------------------------------
Processing model 7...
Loaded embeddings with shape: (323432, 100)
Traceback (most recent call last):
  File "/home/gpuuser1/gpuuser1_a/sandeep/sandeep/ndd/Neighbourhood quality/KNN_learning-opt3.py", line 124, in <module>
    main()
  File "/home/gpuuser1/gpuuser1_a/sandeep/sandeep/ndd/Neighbourhood quality/KNN_learning-opt3.py", line 101, in main
    subsample_labels = train_labels[subsample_indices]
IndexError: index 222384 is out of bounds for axis 0 with size 40429
Completed processing for model 7
------------------------------
Processing model 8...
Loaded embeddings with shape: (323432, 100)
Traceback (most recent call last):
  File "/home/gpuuser1/gpuuser1_a/sandeep/sandeep/ndd/Neighbourhood quality/KNN_learning-opt3.py", line 124, in <module>
    main()
  File "/home/gpuuser1/gpuuser1_a/sandeep/sandeep/ndd/Neighbourhood quality/KNN_learning-opt3.py", line 101, in main
    subsample_labels = train_labels[subsample_indices]
IndexError: index 84538 is out of bounds for axis 0 with size 40429
Completed processing for model 8
------------------------------
Processing model 9...
Loaded embeddings with shape: (323432, 100)
Traceback (most recent call last):
  File "/home/gpuuser1/gpuuser1_a/sandeep/sandeep/ndd/Neighbourhood quality/KNN_learning-opt3.py", line 124, in <module>
    main()
  File "/home/gpuuser1/gpuuser1_a/sandeep/sandeep/ndd/Neighbourhood quality/KNN_learning-opt3.py", line 101, in main
    subsample_labels = train_labels[subsample_indices]
IndexError: index 122977 is out of bounds for axis 0 with size 40429
Completed processing for model 9
------------------------------
Processing model 10...
Loaded embeddings with shape: (323432, 100)
Traceback (most recent call last):
  File "/home/gpuuser1/gpuuser1_a/sandeep/sandeep/ndd/Neighbourhood quality/KNN_learning-opt3.py", line 124, in <module>
    main()
  File "/home/gpuuser1/gpuuser1_a/sandeep/sandeep/ndd/Neighbourhood quality/KNN_learning-opt3.py", line 101, in main
    subsample_labels = train_labels[subsample_indices]
IndexError: index 88103 is out of bounds for axis 0 with size 40429
Completed processing for model 10
------------------------------
Processing model 11...
Loaded embeddings with shape: (323432, 100)
Traceback (most recent call last):
  File "/home/gpuuser1/gpuuser1_a/sandeep/sandeep/ndd/Neighbourhood quality/KNN_learning-opt3.py", line 124, in <module>
    main()
  File "/home/gpuuser1/gpuuser1_a/sandeep/sandeep/ndd/Neighbourhood quality/KNN_learning-opt3.py", line 101, in main
    subsample_labels = train_labels[subsample_indices]
IndexError: index 86842 is out of bounds for axis 0 with size 40429
Completed processing for model 11
------------------------------
Processing model 12...
Loaded embeddings with shape: (323432, 100)
Traceback (most recent call last):
  File "/home/gpuuser1/gpuuser1_a/sandeep/sandeep/ndd/Neighbourhood quality/KNN_learning-opt3.py", line 124, in <module>
    main()
  File "/home/gpuuser1/gpuuser1_a/sandeep/sandeep/ndd/Neighbourhood quality/KNN_learning-opt3.py", line 101, in main
    subsample_labels = train_labels[subsample_indices]
IndexError: index 121437 is out of bounds for axis 0 with size 40429
Completed processing for model 12
------------------------------
Processing model 13...
Loaded embeddings with shape: (323432, 100)
Traceback (most recent call last):
  File "/home/gpuuser1/gpuuser1_a/sandeep/sandeep/ndd/Neighbourhood quality/KNN_learning-opt3.py", line 124, in <module>
    main()
  File "/home/gpuuser1/gpuuser1_a/sandeep/sandeep/ndd/Neighbourhood quality/KNN_learning-opt3.py", line 101, in main
    subsample_labels = train_labels[subsample_indices]
IndexError: index 193574 is out of bounds for axis 0 with size 40429
Completed processing for model 13
------------------------------
Processing model 14...
Loaded embeddings with shape: (323432, 100)
Traceback (most recent call last):
  File "/home/gpuuser1/gpuuser1_a/sandeep/sandeep/ndd/Neighbourhood quality/KNN_learning-opt3.py", line 124, in <module>
    main()
  File "/home/gpuuser1/gpuuser1_a/sandeep/sandeep/ndd/Neighbourhood quality/KNN_learning-opt3.py", line 101, in main
    subsample_labels = train_labels[subsample_indices]
IndexError: index 124718 is out of bounds for axis 0 with size 40429
Completed processing for model 14
------------------------------
Processing model 15...
Loaded embeddings with shape: (323432, 100)
Traceback (most recent call last):
  File "/home/gpuuser1/gpuuser1_a/sandeep/sandeep/ndd/Neighbourhood quality/KNN_learning-opt3.py", line 124, in <module>
    main()
  File "/home/gpuuser1/gpuuser1_a/sandeep/sandeep/ndd/Neighbourhood quality/KNN_learning-opt3.py", line 101, in main
    subsample_labels = train_labels[subsample_indices]
IndexError: index 40752 is out of bounds for axis 0 with size 40429
Completed processing for model 15
------------------------------
All models processed!
